Workbook
Name Slicer_Month: #N/A
Name Slicer_Month1: #N/A
Name Slicer_Month2: #N/A
Name Slicer_Month3: #N/A

Sheet Total Expenses(Chart)
A1: Row Labels | B1: Sum of Salary to be Paid
A2: Consultant | B2: 0.12287441
A3: Employee | B3: 0.87712559
A4: Grand Total | B4: 1

Sheet HR&Consultant
A1: Row Labels | B1: Sum of Salary to be Paid
A2: Consultant | B2: 720147
A3: Grand Total | B3: 720147

Sheet SSPL
A1: Sr. No. | B1: Employee Name | C1: Notes | D1: Employee Code | E1: Working Days | F1: Employee Working Days | G1: Taken Leave | H1: Deductible Leave | I1: Salary after Leave Deduction | J1: Employee Type | K1: PF | L1: ESI | M1: NPS | N1: Professional TAX | O1: Total Deduction | P1: Difference from Last Month / Advance Pay / Loan EMI | Q1: Bonus / Encashment / Reimbursment | R1: TDS | S1: Other Deduction/Salary Hold | T1: Salary to be Paid
A2: 1 | B2: Ajay Jikadra | D2: 297 | E2: 22 | F2: 22 | G2: 0 | H2: 0 | I2: 50000 | J2: Employee | K2: 3600 | L2: 2000 | M2: 0 | N2: 0 | O2: 5600 | R2: 0 | T2: 44400
A3: 2 | B3: Ajay Khavas | C3: DOJ 9th Mar | D3: 304 | E3: 22 | F3: 17 | G3: 0 | H3: 0 | I3: 38636.364 | J3: Employee | K3: 0 | L3: 0 | M3: 0 | N3: 200 | O3: 200 | R3: 0 | T3: 38436
A4: 3 | B4: Akanshi Jain | C4: Parttime Consultant | E4: 22 | F4: 22 | G4: 0 | H4: 0 | I4: 50000 | J4: Consultant | K4: 0 | L4: 0 | M4: 0 | N4: 0 | O4: 0 | R4: 500 | T4: 49500
A5: 4 | B5: Akash Rathor | D5: 249 | E5: 22 | F5: 22 | G5: 1 | H5: 0 | I5: 50000 | J5: Employee | K5: 0 | L5: 0 | M5: 0 | N5: 200 | O5: 200 | R5: 0 | T5: 49800
A6: 5 | B6: Akash Sheth | D6: 273 | E6: 22 | F6: 22 | G6: 0 | H6: 0 | I6: 50000 | J6: Employee | K6: 3600 | L6: 0 | M6: 1250 | N6: 200 | O6: 5050 | R6: 3303 | T6: 41647
A7: 6 | B7: Akshay Patel | D7: 264 | E7: 22 | F7: 22 | G7: 1 | H7: 0 | I7: 50000 | J7: Employee | K7: 3600 | L7: 0 | M7: 0 | N7: 200 | O7: 3800 | R7: 3256 | T7: 42944
A8: 7 | B8: Amir Khan | C8: DOJ 20th Mar | D8: 309 | E8: 22 | F8: 10 | G8: 0 | H8: 0 | I8: 22727.273 | J8: Employee | K8: 0 | L8: 0 | M8: 0 | N8: 200 | O8: 200 | R8: 0 | T8: 22527
A9: 8 | B9: Anandi Pattani | D9: 276 | E9: 22 | F9: 22 | G9: 1 | H9: 0 | I9: 50000 | J9: Employee | K9: 0 | L9: 0 | M9: 0 | N9: 200 | O9: 200 | R9: 0 | T9: 49800
A10: 9 | B10: Anil Babubhai Variya | D10: 164 | E10: 22 | F10: 22 | G10: 0.5 | H10: 0 | I10: 50000 | J10: Employee | K10: 0 | L10: 0 | M10: 0 | N10: 200 | O10: 200 | Q10: 16138 | R10: 14016 | T10: 51922
A11: 10 | B11: Ankit Donda | C11: Freelancer | E11: 22 | F11: 22 | G11: 0 | H11: 0 | I11: 50000 | J11: Consultant | K11: 0 | L11: 0 | M11: 0 | N11: 0 | O11: 0 | R11: 500 | T11: 49500
A12: 11 | B12: Ankit Prajapati | D12: 236 | E12: 22 | F12: 22 | G12: 0 | H12: 0 | I12: 50000 | J12: Employee | K12: 0 | L12: 0 | M12: 0 | N12: 200 | O12: 200 | R12: 17900 | T12: 31900
A13: 12 | B13: Ankita Bharat Ranpariya | C13: Freelancer | E13: 22 | F13: 22 | G13: 0 | H13: 0 | I13: 50000 | J13: Consultant | K13: 0 | L13: 0 | M13: 0 | N13: 0 | O13: 0 | R13: 500 | T13: 49500
A14: 13 | B14: Ankita Damani | C14: Salary Already Paid | E14: 22 | F14: 22 | G14: 0 | H14: 0 | I14: 50000 | J14: Employee | K14: 0 | L14: 0 | M14: 0 | N14: 200 | O14: 200 | R14: 0 | T14: 49800
A15: 14 | B15: Ankur Paranjpe | D15: 294 | E15: 22 | F15: 22 | G15: 0 | H15: 0 | I15: 50000 | J15: Employee | K15: 3600 | L15: 0 | M15: 0 | N15: 200 | O15: 3800 | R15: 24906 | T15: 21294
A16: 15 | B16: Anmol Hariombhai Chaudhary | D16: 151 | E16: 22 | F16: 22 | G16: 0 | H16: 0 | I16: 50000 | J16: Employee | K16: 0 | L16: 0 | M16: 0 | N16: 200 | O16: 200 | R16: 7626 | T16: 42174
A17: 16 | B17: Arjun Lal Rabari | D17: 116 | E17: 22 | F17: 22 | G17: 0 | H17: 0 | I17: 50000 | J17: Employee | K17: 3600 | L17: 2000 | M17: 0 | N17: 200 | O17: 5800 | P17: 15000 | R17: 0 | T17: 29200
A18: 17 | B18: Arpita Harshadbhai Patel | D18: 140 | E18: 22 | F18: 22 | G18: 2 | H18: 0 | I18: 50000 | J18: Employee | K18: 0 | L18: 0 | M18: 0 | N18: 200 | O18: 200 | R18: 0 | T18: 49800
A19: 18 | B19: ARTI CHINTAN KOTHARI | C19: Salary Already Paid | E19: 22 | F19: 22 | G19: 0 | H19: 0 | I19: 50000 | J19: Employee | K19: 0 | L19: 0 | M19: 0 | N19: 200 | O19: 200 | R19: 0 | T19: 49800
A20: 19 | B20: Ashish Mansukhbhai Chaniyara | D20: 141 | E20: 22 | F20: 22 | G20: 1.5 | H20: 0 | I20: 50000 | J20: Employee | K20: 0 | L20: 0 | M20: 0 | N20: 200 | O20: 200 | R20: 0 | T20: 49800
A21: 20 | B21: Ashish Sharma | D21: 257 | E21: 22 | F21: 22 | G21: 0 | H21: 0 | I21: 50000 | J21: Employee | K21: 0 | L21: 0 | M21: 0 | N21: 200 | O21: 200 | R21: 12599 | T21: 37201
A22: 21 | B22: Ashwin Narendrabhai Patel | D22: 42 | E22: 22 | F22: 22 | G22: 0 | H22: 0 | I22: 50000 | J22: Employee | K22: 0 | L22: 0 | M22: 0 | N22: 200 | O22: 200 | R22: 0 | T22: 49800
A23: 22 | B23: Avaiya Dharmeshkumar Haribhai | C23: Freelancer | E23: 22 | F23: 22 | G23: 0 | H23: 0 | I23: 50000 | J23: Consultant | K23: 0 | L23: 0 | M23: 0 | N23: 0 | O23: 0 | R23: 500 | T23: 49500
A24: 23 | B24: Avani Ashvinbhai Patel | D24: 66 | E24: 22 | F24: 22 | G24: 0 | H24: 0 | I24: 50000 | J24: Employee | K24: 3600 | L24: 0 | M24: 0 | N24: 200 | O24: 3800 | P24: 22222 | R24: 12000 | T24: 11978
A25: 24 | B25: Bansi Gothi | D25: 269 | E25: 22 | F25: 22 | G25: 0 | H25: 0 | I25: 50000 | J25: Employee | K25: 0 | L25: 0 | M25: 0 | N25: 200 | O25: 200 | R25: 0 | T25: 49800
A26: 25 | B26: Bansi Jayantibhai Sojitra | D26: 4 | E26: 22 | F26: 22 | G26: 0 | H26: 0 | I26: 50000 | J26: Employee | K26: 0 | L26: 0 | M26: 0 | N26: 200 | O26: 200 | R26: 0 | T26: 49800
A27: 26 | B27: Bharat Kadchha | D27: 225 | E27: 22 | F27: 22 | G27: 6 | H27: 0 | I27: 50000 | J27: Employee | K27: 3600 | L27: 0 | M27: 0 | N27: 200 | O27: 3800 | R27: 0 | T27: 46200
A28: 27 | B28: Bhartiben Italiya | C28: Salary Already Paid | E28: 22 | F28: 22 | G28: 0 | H28: 0 | I28: 50000 | J28: Employee | K28: 0 | L28: 0 | M28: 0 | N28: 200 | O28: 200 | R28: 0 | T28: 49800
A29: 28 | B29: Bhatt Krupa Pradipbhai | D29: 165 | E29: 22 | F29: 22 | G29: 2 | H29: 0 | I29: 50000 | J29: Employee | K29: 0 | L29: 0 | M29: 0 | N29: 200 | O29: 200 | R29: 0 | T29: 49800
A30: 29 | B30: Bhavik Kiri | D30: 300 | E30: 22 | F30: 22 | G30: 0 | H30: 0 | I30: 50000 | J30: Employee | K30: 3600 | L30: 0 | M30: 0 | N30: 200 | O30: 3800 | R30: 0 | T30: 46200
A31: 30 | B31: Bhumi Shah | D31: 255 | E31: 22 | F31: 22 | G31: 1 | H31: 0 | I31: 50000 | J31: Employee | K31: 3600 | L31: 0 | M31: 0 | N31: 200 | O31: 3800 | R31: 0 | T31: 46200
A32: 31 | B32: Bikash Harenhandra Bhakat | D32: 131 | E32: 22 | F32: 22 | G32: 1.5 | H32: 0 | I32: 50000 | J32: Employee | K32: 3600 | L32: 0 | M32: 1250 | N32: 200 | O32: 5050 | R32: 0 | T32: 44950
A33: 32 | B33: Binal Rajeshbhai Kharecha | D33: 22 | E33: 22 | F33: 22 | G33: 0.5 | H33: 0 | I33: 50000 | J33: Employee | K33: 0 | L33: 0 | M33: 0 | N33: 200 | O33: 200 | R33: 0 | T33: 49800
A34: 33 | B34: Chaitali Deepakbhai Zaveri | C34: Resigned on 17th Feb-Salary on Hold | E34: 22 | F34: 22 | G34: 0 | H34: 0 | I34: 50000 | J34: Employee | K34: 3600 | L34: 0 | M34: 0 | N34: 200 | O34: 3800 | R34: 0 | T34: 46200
A35: 34 | B35: Chaitnya Parikh | C35: Last Salary F&F | E35: 22 | F35: 12 | G35: 0 | H35: 0 | I35: 27272.727 | J35: Employee | K35: 3600 | L35: 0 | M35: 0 | N35: 200 | O35: 3800 | R35: 0 | T35: 23473
A36: 35 | B36: Chaitrali Gajjar | C36: DOJ 9th Mar | D36: 305 | E36: 22 | F36: 17 | G36: 1 | H36: 0 | I36: 38636.364 | J36: Employee | K36: 0 | L36: 0 | M36: 0 | N36: 200 | O36: 200 | R36: 0 | T36: 38436
A37: 36 | B37: Chetana Ramasare Ravat | D37: 137 | E37: 22 | F37: 22 | G37: 1 | H37: 0 | I37: 50000 | J37: Employee | K37: 3600 | L37: 0 | M37: 0 | N37: 200 | O37: 3800 | P37: 33333 | R37: 0 | T37: 12867
A38: 37 | B38: Chirag Gujarati | D38: 274 | E38: 22 | F38: 22 | G38: 0 | H38: 0 | I38: 50000 | J38: Employee | K38: 3600 | L38: 0 | M38: 0 | N38: 200 | O38: 3800 | R38: 0 | T38: 46200
A39: 38 | B39: Darshan Rasikbhai Chudasama | D39: 90 | E39: 22 | F39: 22 | G39: 6 | H39: 0 | I39: 50000 | J39: Employee | K39: 3600 | L39: 0 | M39: 0 | N39: 200 | O39: 3800 | R39: 13325 | T39: 32875
A40: 39 | B40: Darshana Patel | D40: 90 | E40: 22 | F40: 22 | G40: 0 | H40: 0 | I40: 50000 | J40: Employee | K40: 0 | L40: 0 | M40: 0 | N40: 200 | O40: 200 | P40: 34800 | R40: 0 | T40: 15000
...

Sheet CR&DR
A1: Row Labels | B1: Sum of Balance
A2: CR | B2: 0.20257873
A3: DR | B3: 0.79742127
A4: Grand Total | B4: 1

Sheet SBI
A1: Sl. No. | B1: Date | C1: Month | D1: Description | E1: Chq / Ref number | F1: Amount | G1: Dr / Cr | H1: Balance | I1: Dr / Cr2
A2: 1 | B2: 45016 | C2: March | D2: FD PREMAT PROCEEDS: 7951700057 | E2: 7951700057TO | F2: 199307 | G2: CR | H2: 42939146 | I2: CR
A3: 2 | B3: 45015 | C3: March | D3: Sweep Trf From: 7951700057 | F3: 361074 | G3: CR | H3: 43300220 | I3: CR
A4: 3 | B4: 45015 | C4: March | D4: DOLLY SHAH | E4: FCM-2303313P87OZ | F4: 79983 | G4: DR | H4: 43380203 | I4: CR
A5: 4 | B5: 45015 | C5: March | D5: HR MANAGEMENT AND PROJECTS PVT LTD | E5: FCM-2303313P87OW | F5: 301939 | G5: DR | H5: 43078264 | I5: CR
A6: 5 | B6: 45015 | C6: March | D6: HR MANAGEMENT AND PROJECTS PVT LTD | E6: FCM-2303313P87OY | F6: 430740 | G6: DR | H6: 42647524 | I6: CR
A7: 6 | B7: 45015 | C7: March | D7: EMA HOSPITALITY SERVICE APPARTMENT | E7: FCM-2303313P87OX | F7: 76229 | G7: DR | H7: 42571295 | I7: CR
A8: 7 | B8: 45015 | C8: March | D8: FD PREMAT PROCEEDS: 7951700057 | E8: 7951700057TO | F8: 155170 | G8: CR | H8: 42416125 | I8: CR
A9: 8 | B9: 45015 | C9: March | D9: Sweep Trf From: 7951700057 | F9: 446588 | G9: CR | H9: 42862713 | I9: CR | L9: First | M9: Last | N9: Month | O9: Opening Balance | P9: Closing Balance
A10: 9 | B10: 45015 | C10: March | D10: PRIVA UMNAG THAKKAR | E10: FCM-2303303ODRL5 | F10: 15109 | G10: DR | H10: 42877822 | I10: DR | L10: 44927 | M10: 44957 | N10: =TEXT(M10,"mmmm") -> January | O10: =INDEX(Table_BankStatement_14[Balance],MATCH(DATEVALUE(TEXT(L10,"dd-mm-yyyy")),Table_BankStatement_14[Date],0))+Table1[[#This Row],[Opening Balance]] -> #N/A | P10: =INDEX(Table_BankStatement_14[Balance],MATCH(DATEVALUE(TEXT(Table16[[#This Row],[Last]],"dd-mm-yyyy")),Table_BankStatement_14[Date],0))+Table1[[#This Row],[Closing Balance]] -> #N/A
A11: 10 | B11: 45015 | C11: March | D11: PRASHANT THAKKAR | E11: FCM-2303303ODRL6 | F11: 55859 | G11: DR | H11: 42821963 | I11: DR | L11: 44958 | M11: 44985 | N11: =TEXT(M11,"mmmm") -> February | O11: =INDEX(Table_BankStatement_14[Balance],MATCH(DATEVALUE(TEXT(L11,"dd-mm-yyyy")),Table_BankStatement_14[Date],0))+Table1[[#This Row],[Opening Balance]] -> #N/A | P11: =INDEX(Table_BankStatement_14[Balance],MATCH(DATEVALUE(TEXT(Table16[[#This Row],[Last]],"dd-mm-yyyy")),Table_BankStatement_14[Date],0))+Table1[[#This Row],[Closing Balance]] -> #N/A
A12: 11 | B12: 45015 | C12: March | D12: PRASHANT THAKKAR HUF | E12: FCM-2303303ODRL4 | F12: 128867 | G12: DR | H12: 42693096 | I12: DR | L12: 44986 | M12: 45016 | N12: =TEXT(M12,"mmmm") -> March | O12: =INDEX(Table_BankStatement_14[Balance],MATCH(DATEVALUE(TEXT(L12,"dd-mm-yyyy")),Table_BankStatement_14[Date],0))+Table1[[#This Row],[Opening Balance]] -> 312297 | P12: =INDEX(Table_BankStatement_14[Balance],MATCH(DATEVALUE(TEXT(Table16[[#This Row],[Last]],"dd-mm-yyyy")),Table_BankStatement_14[Date],0))+Table1[[#This Row],[Closing Balance]] -> 64408719
A13: 12 | B13: 45015 | C13: March | D13: SAPNA DEVANG SHAH | E13: FCM-2303303ODL5I | F13: 90560 | G13: DR | H13: 42602536 | I13: DR | L13: 45017 | M13: 45046 | N13: =TEXT(M13,"mmmm") -> April | O13: =INDEX(Table_BankStatement_14[Balance],MATCH(DATEVALUE(TEXT(L13,"dd-mm-yyyy")),Table_BankStatement_14[Date],0))+Table1[[#This Row],[Opening Balance]] -> 64408719 | P13: =INDEX(Table_BankStatement_14[Balance],MATCH(DATEVALUE(TEXT(Table16[[#This Row],[Last]],"dd-mm-yyyy")),Table_BankStatement_14[Date],0))+Table1[[#This Row],[Closing Balance]] -> 4048117.5
A14: 13 | B14: 45015 | C14: March | D14: ANKITA DARSHAN DAMANI | E14: FCM-2303303ODL5J | F14: 224695 | G14: DR | H14: 42377841 | I14: DR | L14: 45047 | M14: 45077 | N14: =TEXT(M14,"mmmm") -> May | O14: =INDEX(Table_BankStatement_14[Balance],MATCH(DATEVALUE(TEXT(L14,"dd-mm-yyyy")),Table_BankStatement_14[Date],0))+Table1[[#This Row],[Opening Balance]] -> #N/A | P14: =INDEX(Table_BankStatement_14[Balance],MATCH(DATEVALUE(TEXT(Table16[[#This Row],[Last]],"dd-mm-yyyy")),Table_BankStatement_14[Date],0))+Table1[[#This Row],[Closing Balance]] -> #N/A | S14: Row Labels | T14: Sum of Opening Balance | U14: Sum of Closing Balance
A15: 14 | B15: 45015 | C15: March | D15: SHAH MITTALBEN | E15: FCM-2303303ODL5H | F15: 495621 | G15: DR | H15: 41882220 | I15: DR | L15: 45078 | M15: 45107 | N15: =TEXT(M15,"mmmm") -> June | O15: =INDEX(Table_BankStatement_14[Balance],MATCH(DATEVALUE(TEXT(L15,"dd-mm-yyyy")),Table_BankStatement_14[Date],0))+Table1[[#This Row],[Opening Balance]] -> #N/A | P15: =INDEX(Table_BankStatement_14[Balance],MATCH(DATEVALUE(TEXT(Table16[[#This Row],[Last]],"dd-mm-yyyy")),Table_BankStatement_14[Date],0))+Table1[[#This Row],[Closing Balance]] -> #N/A | S15: March | T15: 312297 | U15: 64408719
A16: 15 | B16: 45015 | C16: March | D16: DHRUVI BHAVIKKUMAR DAMANI | E16: FCM-2303303ODL5G | F16: 55323 | G16: DR | H16: 41826897 | I16: DR | L16: 45108 | M16: 45138 | N16: =TEXT(M16,"mmmm") -> July | O16: =INDEX(Table_BankStatement_14[Balance],MATCH(DATEVALUE(TEXT(L16,"dd-mm-yyyy")),Table_BankStatement_14[Date],0))+Table1[[#This Row],[Opening Balance]] -> #N/A | P16: =INDEX(Table_BankStatement_14[Balance],MATCH(DATEVALUE(TEXT(Table16[[#This Row],[Last]],"dd-mm-yyyy")),Table_BankStatement_14[Date],0))+Table1[[#This Row],[Closing Balance]] -> #N/A
A17: 16 | B17: 45015 | C17: March | D17: MANIYAR KHUSHBOO DHAVALKUMAR | E17: FCM-2303303ODL5F | F17: 249001 | G17: DR | H17: 41577896 | I17: DR | L17: 45139 | M17: 45169 | N17: =TEXT(M17,"mmmm") -> August | O17: =INDEX(Table_BankStatement_14[Balance],MATCH(DATEVALUE(TEXT(L17,"dd-mm-yyyy")),Table_BankStatement_14[Date],0))+Table1[[#This Row],[Opening Balance]] -> #N/A | P17: =INDEX(Table_BankStatement_14[Balance],MATCH(DATEVALUE(TEXT(Table16[[#This Row],[Last]],"dd-mm-yyyy")),Table_BankStatement_14[Date],0))+Table1[[#This Row],[Closing Balance]] -> #N/A
A18: 17 | B18: 45015 | C18: March | D18: KETA UMANGKUMAR THAKKAR | E18: FCM-2303303ODL5E | F18: 46373 | G18: DR | H18: 41531523 | I18: DR | L18: 45170 | M18: 45199 | N18: =TEXT(M18,"mmmm") -> September | O18: =INDEX(Table_BankStatement_14[Balance],MATCH(DATEVALUE(TEXT(L18,"dd-mm-yyyy")),Table_BankStatement_14[Date],0))+Table1[[#This Row],[Opening Balance]] -> #N/A | P18: =INDEX(Table_BankStatement_14[Balance],MATCH(DATEVALUE(TEXT(Table16[[#This Row],[Last]],"dd-mm-yyyy")),Table_BankStatement_14[Date],0))+Table1[[#This Row],[Closing Balance]] -> #N/A
A19: 18 | B19: 45015 | C19: March | D19: ARTI CHINTAN KOTHARI | E19: FCM-2303303ODRPT | F19: 351996 | G19: DR | H19: 41179527 | I19: DR | L19: 45200 | M19: 45230 | N19: =TEXT(M19,"mmmm") -> October | O19: =INDEX(Table_BankStatement_14[Balance],MATCH(DATEVALUE(TEXT(L19,"dd-mm-yyyy")),Table_BankStatement_14[Date],0))+Table1[[#This Row],[Opening Balance]] -> #N/A | P19: =INDEX(Table_BankStatement_14[Balance],MATCH(DATEVALUE(TEXT(Table16[[#This Row],[Last]],"dd-mm-yyyy")),Table_BankStatement_14[Date],0))+Table1[[#This Row],[Closing Balance]] -> #N/A
A20: 19 | B20: 45015 | C20: March | D20: KESHAV RAJKUMAR AGARWAL | E20: FCM-2303303ODRPY | F20: 473570 | G20: DR | H20: 40705957 | I20: DR | L20: 45231 | M20: 45260 | N20: =TEXT(M20,"mmmm") -> November | O20: =INDEX(Table_BankStatement_14[Balance],MATCH(DATEVALUE(TEXT(L20,"dd-mm-yyyy")),Table_BankStatement_14[Date],0))+Table1[[#This Row],[Opening Balance]] -> #N/A | P20: =INDEX(Table_BankStatement_14[Balance],MATCH(DATEVALUE(TEXT(Table16[[#This Row],[Last]],"dd-mm-yyyy")),Table_BankStatement_14[Date],0))+Table1[[#This Row],[Closing Balance]] -> #N/A
A21: 20 | B21: 45015 | C21: March | D21: DISHA NIKHIL SANANDIYA | E21: FCM-2303303ODRPU | F21: 334761 | G21: DR | H21: 40371196 | I21: CR | L21: 45261 | M21: 45291 | N21: =TEXT(M21,"mmmm") -> December | O21: =INDEX(Table_BankStatement_14[Balance],MATCH(DATEVALUE(TEXT(L21,"dd-mm-yyyy")),Table_BankStatement_14[Date],0))+Table1[[#This Row],[Opening Balance]] -> #N/A | P21: =INDEX(Table_BankStatement_14[Balance],MATCH(DATEVALUE(TEXT(Table16[[#This Row],[Last]],"dd-mm-yyyy")),Table_BankStatement_14[Date],0))+Table1[[#This Row],[Closing Balance]] -> #N/A
A22: 21 | B22: 45015 | C22: March | D22: KRUTI MANISHKUMAR BAGADIA | E22: FCM-2303303ODRPW | F22: 211697 | G22: DR | H22: 40159499 | I22: CR
A23: 22 | B23: 45015 | C23: March | D23: S N D J CONSULTANTS PVT LTD | E23: FCM-2303303ODRPS | F23: 20245 | G23: DR | H23: 40139254 | I23: CR
A24: 23 | B24: 45015 | C24: March | D24: MANISHA MAKHIYAVIYA | E24: FCM-2303303ODRPV | F24: 244094 | G24: DR | H24: 39895160 | I24: CR
A25: 24 | B25: 45015 | C25: March | D25: BHARTIBEN TUSHARKUMAR ITALIYA | E25: FCM-2303303ODRPX | F25: 107121 | G25: DR | H25: 39788039 | I25: CR
A26: 25 | B26: 45013 | C26: March | D26: Sweep Trf From: 7951700057 | F26: 124901 | G26: CR | H26: 39663138 | I26: CR
A27: 26 | B27: 45013 | C27: March | D27: PG CREDIT CARD KOTAKCARD | E27: KPG-0185860263 | F27: 440765 | G27: DR | H27: 40103903 | I27: CR
A28: 27 | B28: 45012 | C28: March | D28: Sweep Trf From: 7951700057 | F28: 97275 | G28: CR | H28: 40006628 | I28: CR
A29: 28 | B29: 45012 | C29: March | D29: NEFT-EVERGREEN CORPORATE -CMS0862348056537 | E29: FCM-2303273N39MU | F29: 497243 | G29: DR | H29: 40503871 | I29: CR
A30: 29 | B30: 45009 | C30: March | D30: Sweep Trf From: 7951700057 | F30: 91960 | G30: CR | H30: 40411911 | I30: CR
A31: 30 | B31: 45009 | C31: March | D31: NEFT-AVION CLOUD SOLUTION-CMS0832347793565 | E31: FCM-2303233M3KOS | F31: 441758 | G31: DR | H31: 40853669 | I31: CR
A32: 31 | B32: 45008 | C32: March | D32: SWEEP TRANSFER TO [7951700057] | F32: 42782 | G32: DR | H32: 40810887 | I32: CR
A33: 32 | B33: 45008 | C33: March | D33: MB:SENT TO KMBL- COLLECTION ACCOUNT- NPS -NPS TRU | E33: MB-998923096053 | F33: 34136 | G33: DR | H33: 40776751 | I33: CR
A34: 33 | B34: 45008 | C34: March | D34: 2587MIS231161949 CRE001 GENOME MEDICAL INC | E34: TIP-b29881d1-492c-45 | F34: 140985 | G34: CR | H34: 40635766 | I34: CR
A35: 34 | B35: 45008 | C35: March | D35: 2587MIS231161949 CRE001 FCC-GOODS AND SERVICES TA | E35: TIP-b29881d1-492c-45 | F35: 89801 | G35: DR | H35: 40725567 | I35: CR
A36: 35 | B36: 45008 | C36: March | D36: 2587MIS231161916 CRE001 FCC-GOODS AND SERVICES TA | E36: TIP-3348372f-3fc5-4b | F36: 330991 | G36: DR | H36: 40394576 | I36: CR
A37: 36 | B37: 45008 | C37: March | D37: 2587MIS231161916 CRE001 EGALVANIC LLC | E37: TIP-3348372f-3fc5-4b | F37: 21530 | G37: CR | H37: 40373046 | I37: CR
A38: 37 | B38: 45008 | C38: March | D38: NEFT NRE REM INTELLIANTE INC BRENTDAVIDHOLLAND C | E38: NEFTINW-0561877713 | F38: 208207 | G38: CR | H38: 40581253 | I38: CR
A39: 38 | B39: 45007 | C39: March | D39: SWEEP TRANSFER TO [7951677370] | F39: 217891 | G39: DR | H39: 40799144 | I39: CR
A40: 39 | B40: 45007 | C40: March | D40: MB:RECEIVED FROM PANCHAL VISHAL ARVINDBHAI/INSTALL | E40: MB-998923876213 | F40: 361138 | G40: CR | H40: 40438006 | I40: CR
...

Sheet Kotak
A1: Sl. No. | B1: Date | C1: Month | D1: Description | E1: Chq / Ref number | F1: Amount | G1: Dr / Cr | H1: Balance | I1: Dr / Cr2
A2: 1 | B2: 45016 | C2: March | D2: FD PREMAT PROCEEDS: 7951700057 | E2: 7951700057TO | F2: 199307 | G2: CR | H2: =Table_BankStatement_14[[#This Row],[Balance]]/2 -> 21469573 | I2: CR
A3: 2 | B3: 45015 | C3: March | D3: Sweep Trf From: 7951700057 | F3: 361074 | G3: CR | H3: =Table_BankStatement_14[[#This Row],[Balance]]/2 -> 21650110 | I3: CR
A4: 3 | B4: 45015 | C4: March | D4: DOLLY SHAH | E4: FCM-2303313P87OZ | F4: 79983 | G4: DR | H4: =Table_BankStatement_14[[#This Row],[Balance]]/2 -> 21690102 | I4: CR
A5: 4 | B5: 45015 | C5: March | D5: HR MANAGEMENT AND PROJECTS PVT LTD | E5: FCM-2303313P87OW | F5: 301939 | G5: DR | H5: =Table_BankStatement_14[[#This Row],[Balance]]/2 -> 21539132 | I5: CR
A6: 5 | B6: 45015 | C6: March | D6: HR MANAGEMENT AND PROJECTS PVT LTD | E6: FCM-2303313P87OY | F6: 430740 | G6: DR | H6: =Table_BankStatement_14[[#This Row],[Balance]]/2 -> 21323762 | I6: CR
A7: 6 | B7: 45015 | C7: March | D7: EMA HOSPITALITY SERVICE APPARTMENT | E7: FCM-2303313P87OX | F7: 76229 | G7: DR | H7: =Table_BankStatement_14[[#This Row],[Balance]]/2 -> 21285648 | I7: CR
A8: 7 | B8: 45015 | C8: March | D8: FD PREMAT PROCEEDS: 7951700057 | E8: 7951700057TO | F8: 155170 | G8: CR | H8: =Table_BankStatement_14[[#This Row],[Balance]]/2 -> 21208062 | I8: CR
A9: 8 | B9: 45015 | C9: March | D9: Sweep Trf From: 7951700057 | F9: 446588 | G9: CR | H9: =Table_BankStatement_14[[#This Row],[Balance]]/2 -> 21431356 | I9: CR | L9: First | M9: Last | N9: Month | O9: Opening Balance | P9: Closing Balance
A10: 9 | B10: 45015 | C10: March | D10: PRIVA UMNAG THAKKAR | E10: FCM-2303303ODRL5 | F10: 15109 | G10: DR | H10: =Table_BankStatement_14[[#This Row],[Balance]]/2 -> 21438911 | I10: DR | L10: 44927 | M10: 44957 | N10: =TEXT(M10,"mmmm") -> January | O10: =INDEX(Table_BankStatement_1[Balance],MATCH(DATEVALUE(TEXT(L10,"dd-mm-yyyy")),Table_BankStatement_1[Date],0)) -> #N/A | P10: =INDEX(Table_BankStatement_1[Balance],MATCH(DATEVALUE(TEXT(Table1[[#This Row],[Last]],"dd-mm-yyyy")),Table_BankStatement_1[Date],0)) -> #N/A
A11: 10 | B11: 45015 | C11: March | D11: PRASHANT THAKKAR | E11: FCM-2303303ODRL6 | F11: 55859 | G11: DR | H11: =Table_BankStatement_14[[#This Row],[Balance]]/2 -> 21410982 | I11: DR | L11: 44958 | M11: 44985 | N11: =TEXT(M11,"mmmm") -> February | O11: =INDEX(Table_BankStatement_1[Balance],MATCH(DATEVALUE(TEXT(L11,"dd-mm-yyyy")),Table_BankStatement_1[Date],0)) -> #N/A | P11: =INDEX(Table_BankStatement_1[Balance],MATCH(DATEVALUE(TEXT(Table1[[#This Row],[Last]],"dd-mm-yyyy")),Table_BankStatement_1[Date],0)) -> #N/A
A12: 11 | B12: 45015 | C12: March | D12: PRASHANT THAKKAR HUF | E12: FCM-2303303ODRL4 | F12: 128867 | G12: DR | H12: =Table_BankStatement_14[[#This Row],[Balance]]/2 -> 21346548 | I12: DR | L12: 44986 | M12: 45016 | N12: =TEXT(M12,"mmmm") -> March | O12: =INDEX(Table_BankStatement_1[Balance],MATCH(DATEVALUE(TEXT(L12,"dd-mm-yyyy")),Table_BankStatement_1[Date],0)) -> 104099 | P12: =INDEX(Table_BankStatement_1[Balance],MATCH(DATEVALUE(TEXT(Table1[[#This Row],[Last]],"dd-mm-yyyy")),Table_BankStatement_1[Date],0)) -> 21469573
A13: 12 | B13: 45015 | C13: March | D13: SAPNA DEVANG SHAH | E13: FCM-2303303ODL5I | F13: 90560 | G13: DR | H13: =Table_BankStatement_14[[#This Row],[Balance]]/2 -> 21301268 | I13: DR | L13: 45017 | M13: 45046 | N13: =TEXT(M13,"mmmm") -> April | O13: =INDEX(Table_BankStatement_1[Balance],MATCH(DATEVALUE(TEXT(L13,"dd-mm-yyyy")),Table_BankStatement_1[Date],0)) -> 21469573 | P13: =INDEX(Table_BankStatement_1[Balance],MATCH(DATEVALUE(TEXT(Table1[[#This Row],[Last]],"dd-mm-yyyy")),Table_BankStatement_1[Date],0)) -> 1349372.5 | R13: Row Labels | S13: Sum of Closing Balance | T13: Sum of Opening Balance
A14: 13 | B14: 45015 | C14: March | D14: ANKITA DARSHAN DAMANI | E14: FCM-2303303ODL5J | F14: 224695 | G14: DR | H14: =Table_BankStatement_14[[#This Row],[Balance]]/2 -> 21188920 | I14: DR | L14: 45047 | M14: 45077 | N14: =TEXT(M14,"mmmm") -> May | O14: =INDEX(Table_BankStatement_1[Balance],MATCH(DATEVALUE(TEXT(L14,"dd-mm-yyyy")),Table_BankStatement_1[Date],0)) -> #N/A | P14: =INDEX(Table_BankStatement_1[Balance],MATCH(DATEVALUE(TEXT(Table1[[#This Row],[Last]],"dd-mm-yyyy")),Table_BankStatement_1[Date],0)) -> #N/A | R14: April | S14: 1362017 | T14: 21469573
A15: 14 | B15: 45015 | C15: March | D15: SHAH MITTALBEN | E15: FCM-2303303ODL5H | F15: 495621 | G15: DR | H15: =Table_BankStatement_14[[#This Row],[Balance]]/2 -> 20941110 | I15: DR | L15: 45078 | M15: 45107 | N15: =TEXT(M15,"mmmm") -> June | O15: =INDEX(Table_BankStatement_1[Balance],MATCH(DATEVALUE(TEXT(L15,"dd-mm-yyyy")),Table_BankStatement_1[Date],0)) -> #N/A | P15: =INDEX(Table_BankStatement_1[Balance],MATCH(DATEVALUE(TEXT(Table1[[#This Row],[Last]],"dd-mm-yyyy")),Table_BankStatement_1[Date],0)) -> #N/A
A16: 15 | B16: 45015 | C16: March | D16: DHRUVI BHAVIKKUMAR DAMANI | E16: FCM-2303303ODL5G | F16: 55323 | G16: DR | H16: =Table_BankStatement_14[[#This Row],[Balance]]/2 -> 20913448 | I16: DR | L16: 45108 | M16: 45138 | N16: =TEXT(M16,"mmmm") -> July | O16: =INDEX(Table_BankStatement_1[Balance],MATCH(DATEVALUE(TEXT(L16,"dd-mm-yyyy")),Table_BankStatement_1[Date],0)) -> #N/A | P16: =INDEX(Table_BankStatement_1[Balance],MATCH(DATEVALUE(TEXT(Table1[[#This Row],[Last]],"dd-mm-yyyy")),Table_BankStatement_1[Date],0)) -> #N/A
A17: 16 | B17: 45015 | C17: March | D17: MANIYAR KHUSHBOO DHAVALKUMAR | E17: FCM-2303303ODL5F | F17: 249001 | G17: DR | H17: =Table_BankStatement_14[[#This Row],[Balance]]/2 -> 20788948 | I17: DR | L17: 45139 | M17: 45169 | N17: =TEXT(M17,"mmmm") -> August | O17: =INDEX(Table_BankStatement_1[Balance],MATCH(DATEVALUE(TEXT(L17,"dd-mm-yyyy")),Table_BankStatement_1[Date],0)) -> #N/A | P17: =INDEX(Table_BankStatement_1[Balance],MATCH(DATEVALUE(TEXT(Table1[[#This Row],[Last]],"dd-mm-yyyy")),Table_BankStatement_1[Date],0)) -> #N/A
A18: 17 | B18: 45015 | C18: March | D18: KETA UMANGKUMAR THAKKAR | E18: FCM-2303303ODL5E | F18: 46373 | G18: DR | H18: =Table_BankStatement_14[[#This Row],[Balance]]/2 -> 20765762 | I18: DR | L18: 45170 | M18: 45199 | N18: =TEXT(M18,"mmmm") -> September | O18: =INDEX(Table_BankStatement_1[Balance],MATCH(DATEVALUE(TEXT(L18,"dd-mm-yyyy")),Table_BankStatement_1[Date],0)) -> #N/A | P18: =INDEX(Table_BankStatement_1[Balance],MATCH(DATEVALUE(TEXT(Table1[[#This Row],[Last]],"dd-mm-yyyy")),Table_BankStatement_1[Date],0)) -> #N/A
A19: 18 | B19: 45015 | C19: March | D19: ARTI CHINTAN KOTHARI | E19: FCM-2303303ODRPT | F19: 351996 | G19: DR | H19: =Table_BankStatement_14[[#This Row],[Balance]]/2 -> 20589764 | I19: DR | L19: 45200 | M19: 45230 | N19: =TEXT(M19,"mmmm") -> October | O19: =INDEX(Table_BankStatement_1[Balance],MATCH(DATEVALUE(TEXT(L19,"dd-mm-yyyy")),Table_BankStatement_1[Date],0)) -> #N/A | P19: =INDEX(Table_BankStatement_1[Balance],MATCH(DATEVALUE(TEXT(Table1[[#This Row],[Last]],"dd-mm-yyyy")),Table_BankStatement_1[Date],0)) -> #N/A
A20: 19 | B20: 45015 | C20: March | D20: KESHAV RAJKUMAR AGARWAL | E20: FCM-2303303ODRPY | F20: 473570 | G20: DR | H20: =Table_BankStatement_14[[#This Row],[Balance]]/2 -> 20352978 | I20: DR | L20: 45231 | M20: 45260 | N20: =TEXT(M20,"mmmm") -> November | O20: =INDEX(Table_BankStatement_1[Balance],MATCH(DATEVALUE(TEXT(L20,"dd-mm-yyyy")),Table_BankStatement_1[Date],0)) -> #N/A | P20: =INDEX(Table_BankStatement_1[Balance],MATCH(DATEVALUE(TEXT(Table1[[#This Row],[Last]],"dd-mm-yyyy")),Table_BankStatement_1[Date],0)) -> #N/A
A21: 20 | B21: 45015 | C21: March | D21: DISHA NIKHIL SANANDIYA | E21: FCM-2303303ODRPU | F21: 334761 | G21: DR | H21: =Table_BankStatement_14[[#This Row],[Balance]]/2 -> 20185598 | I21: CR | L21: 45261 | M21: 45291 | N21: =TEXT(M21,"mmmm") -> December | O21: =INDEX(Table_BankStatement_1[Balance],MATCH(DATEVALUE(TEXT(L21,"dd-mm-yyyy")),Table_BankStatement_1[Date],0)) -> #N/A | P21: =INDEX(Table_BankStatement_1[Balance],MATCH(DATEVALUE(TEXT(Table1[[#This Row],[Last]],"dd-mm-yyyy")),Table_BankStatement_1[Date],0)) -> #N/A
A22: 21 | B22: 45015 | C22: March | D22: KRUTI MANISHKUMAR BAGADIA | E22: FCM-2303303ODRPW | F22: 211697 | G22: DR | H22: =Table_BankStatement_14[[#This Row],[Balance]]/2 -> 20079750 | I22: CR
A23: 22 | B23: 45015 | C23: March | D23: S N D J CONSULTANTS PVT LTD | E23: FCM-2303303ODRPS | F23: 20245 | G23: DR | H23: =Table_BankStatement_14[[#This Row],[Balance]]/2 -> 20069627 | I23: CR
A24: 23 | B24: 45015 | C24: March | D24: MANISHA MAKHIYAVIYA | E24: FCM-2303303ODRPV | F24: 244094 | G24: DR | H24: =Table_BankStatement_14[[#This Row],[Balance]]/2 -> 19947580 | I24: CR
A25: 24 | B25: 45015 | C25: March | D25: BHARTIBEN TUSHARKUMAR ITALIYA | E25: FCM-2303303ODRPX | F25: 107121 | G25: DR | H25: =Table_BankStatement_14[[#This Row],[Balance]]/2 -> 19894020 | I25: CR
A26: 25 | B26: 45013 | C26: March | D26: Sweep Trf From: 7951700057 | F26: 124901 | G26: CR | H26: =Table_BankStatement_14[[#This Row],[Balance]]/2 -> 19831569 | I26: CR
A27: 26 | B27: 45013 | C27: March | D27: PG CREDIT CARD KOTAKCARD | E27: KPG-0185860263 | F27: 440765 | G27: DR | H27: =Table_BankStatement_14[[#This Row],[Balance]]/2 -> 20051952 | I27: CR
A28: 27 | B28: 45012 | C28: March | D28: Sweep Trf From: 7951700057 | F28: 97275 | G28: CR | H28: =Table_BankStatement_14[[#This Row],[Balance]]/2 -> 20003314 | I28: CR
A29: 28 | B29: 45012 | C29: March | D29: NEFT-EVERGREEN CORPORATE -CMS0862348056537 | E29: FCM-2303273N39MU | F29: 497243 | G29: DR | H29: =Table_BankStatement_14[[#This Row],[Balance]]/2 -> 20251936 | I29: CR
A30: 29 | B30: 45009 | C30: March | D30: Sweep Trf From: 7951700057 | F30: 91960 | G30: CR | H30: =Table_BankStatement_14[[#This Row],[Balance]]/2 -> 20205956 | I30: CR
A31: 30 | B31: 45009 | C31: March | D31: NEFT-AVION CLOUD SOLUTION-CMS0832347793565 | E31: FCM-2303233M3KOS | F31: 441758 | G31: DR | H31: =Table_BankStatement_14[[#This Row],[Balance]]/2 -> 20426834 | I31: CR
A32: 31 | B32: 45008 | C32: March | D32: SWEEP TRANSFER TO [7951700057] | F32: 42782 | G32: DR | H32: =Table_BankStatement_14[[#This Row],[Balance]]/2 -> 20405444 | I32: CR
A33: 32 | B33: 45008 | C33: March | D33: MB:SENT TO KMBL- COLLECTION ACCOUNT- NPS -NPS TRU | E33: MB-998923096053 | F33: 34136 | G33: DR | H33: =Table_BankStatement_14[[#This Row],[Balance]]/2 -> 20388376 | I33: CR
A34: 33 | B34: 45008 | C34: March | D34: 2587MIS231161949 CRE001 GENOME MEDICAL INC | E34: TIP-b29881d1-492c-45 | F34: 140985 | G34: CR | H34: =Table_BankStatement_14[[#This Row],[Balance]]/2 -> 20317883 | I34: CR
A35: 34 | B35: 45008 | C35: March | D35: 2587MIS231161949 CRE001 FCC-GOODS AND SERVICES TA | E35: TIP-b29881d1-492c-45 | F35: 89801 | G35: DR | H35: =Table_BankStatement_14[[#This Row],[Balance]]/2 -> 20362784 | I35: CR
A36: 35 | B36: 45008 | C36: March | D36: 2587MIS231161916 CRE001 FCC-GOODS AND SERVICES TA | E36: TIP-3348372f-3fc5-4b | F36: 330991 | G36: DR | H36: =Table_BankStatement_14[[#This Row],[Balance]]/2 -> 20197288 | I36: CR
A37: 36 | B37: 45008 | C37: March | D37: 2587MIS231161916 CRE001 EGALVANIC LLC | E37: TIP-3348372f-3fc5-4b | F37: 21530 | G37: CR | H37: =Table_BankStatement_14[[#This Row],[Balance]]/2 -> 20186523 | I37: CR
A38: 37 | B38: 45008 | C38: March | D38: NEFT NRE REM INTELLIANTE INC BRENTDAVIDHOLLAND C | E38: NEFTINW-0561877713 | F38: 208207 | G38: CR | H38: =Table_BankStatement_14[[#This Row],[Balance]]/2 -> 20290626 | I38: CR
A39: 38 | B39: 45007 | C39: March | D39: SWEEP TRANSFER TO [7951677370] | F39: 217891 | G39: DR | H39: =Table_BankStatement_14[[#This Row],[Balance]]/2 -> 20399572 | I39: CR
A40: 39 | B40: 45007 | C40: March | D40: MB:RECEIVED FROM PANCHAL VISHAL ARVINDBHAI/INSTALL | E40: MB-998923876213 | F40: 361138 | G40: CR | H40: =Table_BankStatement_14[[#This Row],[Balance]]/2 -> 20219003 | I40: CR
...

Sheet FuzzyLookup_AddIn_Undo_Sheet
A1: Sr No | B1: Employee Code | C1: Column1 | D1: Employee name | E1: Manager Name RM1 | F1: Manager Name RM2 | G1: Table28.Project | H1: Salary to be Paid
A2: 1 | B2: 4 | D2: Bansi Jayantibhai Sojitra | E2: MehulKumar JayeshKumar Patel | F2: Mayur Vinod kumar Jain | G2: VSI-Nationwide | H2: 49800
A3: 49 | B3: 3 | D3: Hetal Arunbhai Agravat | E3: MehulKumar JayeshKumar Patel | F3: Mayur Vinod kumar Jain | G3: VSI-Nationwide | H3: 46200
A4: 2 | B4: 9 | D4: Dhananjay Rajeshbhai Dhobi | E4: Prashant Thakkar | F4: Prashant Thakkar | G4: IFM | H4: 9138
A5: 3 | B5: 18 | D5: Priyank Mahendrabhai Patel | E5: Prashant Thakkar | F5: Prashant Thakkar | G5: Blitzz | H5: -10374
A6: 4 | B6: 13 | D6: Vivek Ashvinbhai Joshi | E6: Prashant Thakkar | F6: Prashant Thakkar | G6: Risk AI/Genome | H6: 30556
A7: 5 | B7: 22 | D7: Binal Rajeshbhai Kharecha | E7: Anil Babubhai Variya | F7: Vishal Prajapati | G7: Blitzz | H7: 49800
A8: 6 | B8: 25 | D8: Kush Kiritkumar Jadia | E8: RITESH JAIN | F8: RITESH JAIN | G8: Vsite-RemoteVal | H8: 40045
A9: 7 | B9: 28 | D9: Vishal Arvindbhai Panchal | E9: Prashant Thakkar | F9: Prashant Thakkar | G9: Genome | H9: 32209
A10: 8 | B10: 38 | D10: Pankti Milap Patel | E10: Arpit Makhiyaviya | F10: Arpit Makhiyaviya | G10: Genome | H10: 24133
A11: 9 | B11: 42 | D11: Ashwin Narendrabhai Patel | E11: Vishal Prajapati | F11: Vishal Prajapati | G11: Blitzz | H11: 49800
A12: 10 | B12: 43 | D12: Mudit Meghraj Parakh | E12: Arpit Makhiyaviya | F12: Arpit Makhiyaviya | G12: Genome | H12: 40032
A13: 11 | B13: 45 | D13: Nitin Tribhovan Makwana | E13: Vishal Prajapati | F13: Vishal Prajapati | G13: Blitzz | H13: 58015
... A88: 107 | B88: 278 | D88: Henil Shah | E88: Ankit Prajapati | F88: Vivek Ashvinbhai Joshi | G88: Risk AI/Genome | H88: 46200
A89: 83 | B89: 290 | D89: Vedkumar Patel | E89: Vainik Kakadiya | F89: Arpit Makhiyaviya | G89: Vsite-RemoteVal
A90: 84 | B90: 291 | D90: Mohit Solanki | E90: Vivek Ashvinbhai Joshi | F90: Vivek Ashvinbhai Joshi | G90: Intelliante | H90: 49800
A91: 85 | B91: 293 | D91: Moin Qureshi | E91: Dhara Mansukhbhai Basida | F91: RITESH JAIN | G91: Vsite-RemoteVal | H91: 46200
A92: 86 | B92: 292 | D92: Vinod Yogi | E92: Dhara Mansukhbhai Basida | F92: RITESH JAIN | G92: Vsite-RemoteVal | H92: 46200
A93: 87 | B93: 294 | D93: Ankur Paranjpe | E93: Vishal Arvindbhai Panchal | F93: Vishal Arvindbhai Panchal | G93: Genome | H93: 21294
A94: 88 | B94: 297 | D94: Ajay Jikadra | E94: Binal Rajeshbhai Kharecha | F94: Vishal Prajapati | G94: Blitzz | H94: 44400
A95: 89 | B95: 298 | D95: Pallav Koshiya | E95: Bikash Harenhandra Bhakat | F95: Dhananjay Rajeshbhai Dhobi | G95: IFM | H95: 46200
A96: 90 | B96: 300 | D96: Bhavik Kiri | E96: Priyank Mahendrabhai Patel | F96: Priyank Mahendrabhai Patel | G96: MED | H96: 46200
A97: 91 | B97: 301 | D97: Sonukumar Gupta | E97: Vivek Ashvinbhai Joshi | F97: Vishal Arvindbhai Panchal | G97: Genome | H97: 33047
A98: 92 | B98: 302 | D98: Nikunj Joshi | E98: Vishal Arvindbhai Panchal | F98: Vishal Arvindbhai Panchal | G98: Genome | H98: 12089
A99: 105 | B99: 295 | D99: Parbat Singh Chouhan | E99: MehulKumar JayeshKumar Patel | F99: Mayur Vinod kumar Jain | G99: VSI-Nationwide | H99: 49800
A100: 93 | B100: 304 | D100: Ajay Khavas | E100: Anil Babubhai Variya | F100: Vishal Prajapati | G100: Blitzz | H100: 38436
A101: 94 | B101: 305 | D101: Chaitrali Gajjar | E101: Vishal Prajapati | F101: Vishal Prajapati | G101: Blitzz | H101: 38436
... A106: 109 | B106: 303 | D106: Zeelkumar Rabadiya | E106: Rahul Manojkumar Parikh | F106: Rahul Manojkumar Parikh | G106: Sensaii | H106: 26745
A107: 99 | B107: 312 | D107: Viral Suhagiya | E107: Vivek Ashvinbhai Joshi | F107: Arpit Makhiyaviya | G107: Risk Ai
A108: 100 | B108: 311 | D108: Parth Munjani | E108: Samarth Rameshbhai Thesiya | F108: Vishal Arvindbhai Panchal | G108: SculptSoft
A109: 101 | B109: 313 | D109: Pranav Nair | E109: Samarth Rameshbhai Thesiya | F109: Vishal Arvindbhai Panchal | G109: Genome
A110: 108 | B110: 310 | D110: Rajesh Bohra | E110: Ashwin Narendrabhai Patel | F110: Ashwin Narendrabhai Patel | G110: Web Design

Sheet Project-Income VS Salary
A1: Row Labels | B1: Sum of Amount Raised in INR | C1: Sum of Salary to be Paid
A2: KIRTI TRADING COMPANY | B2: 2316992 | C2: 230771
A3: SAGAR SALES | B3: 2121176 | C3: 174969
A4: RELIANCE RETAIL LIMITED | B4: 1554064 | C4: 141583
A5: RAJBHARAT CASHEW COMPANY | B5: 3594388 | C5: 305119
A6: J.K.& CO. | B6: 798270 | C6: 128209
A7: PARTH ENTERPRISE | B7: 1538566 | C7: 75215
A8: SAMIR TRADIND CO. | B8: 1576696 | C8: 141247
A9: RADHA DISTRIBUTORS | B9: 7375162 | C9: 741778
A10: MAHAVIR AGENCIES | B10: 1299618 | C10: 111689
A11: DEVHAR MARKETING PVT.LTD | B11: 3622842 | C11: 355124
A12: RAHI ENTERPRISE | B12: 994086 | C12: 118192
A13: TIRUPATI AGENCIES | B13: 507580 | C13: 127649
... A26: PARSHWANATH TRADERS | B26: 1315526 | C26: 133447
A27: (blank)
A28: Grand Total | B28: 40719888 | C28: 4017627

Sheet Employee_manager_project
A1: Sr No | B1: Employee Code | C1: Column1 | D1: Employee name | E1: Manager Name RM1 | F1: Manager Name RM2 | G1: Table28.Project | H1: Salary to be Paid | I1: Month | J1: Amount Raised in INR | K1: Amount Received in INR | L1: Pending Amount
A2: 1 | B2: 4 | D2: Bansi Jayantibhai Sojitra | E2: MehulKumar JayeshKumar Patel | F2: Mayur Vinod kumar Jain | G2: KIRTI TRADING COMPANY | H2: 49800 | I2: March | J2: 305532 | K2: 582610 | L2: 2895
A3: 49 | B3: 3 | D3: Hetal Arunbhai Agravat | E3: MehulKumar JayeshKumar Patel | F3: Mayur Vinod kumar Jain | G3: SAGAR SALES | H3: 46200 | I3: March | J3: 305532 | K3: 582610 | L3: 2895
A4: 2 | B4: 9 | D4: Dhananjay Rajeshbhai Dhobi | E4: Prashant Thakkar | F4: Prashant Thakkar | G4: RELIANCE RETAIL LIMITED | H4: 9138 | I4: April | J4: 492328 | K4: 429516 | L4: 4762
A5: 3 | B5: 18 | D5: Priyank Mahendrabhai Patel | E5: Prashant Thakkar | F5: Prashant Thakkar | G5: RAJBHARAT CASHEW COMPANY | H5: -10374 | I5: April | J5: 740296 | K5: 228370 | L5: 7215
A6: 4 | B6: 13 | D6: Vivek Ashvinbhai Joshi | E6: Prashant Thakkar | F6: Prashant Thakkar | G6: KIRTI TRADING COMPANY | H6: 30556
A7: 5 | B7: 22 | D7: Binal Rajeshbhai Kharecha | E7: Anil Babubhai Variya | F7: Vishal Prajapati | G7: SAGAR SALES | H7: 49800 | I7: April | J7: 740296 | K7: 228370 | L7: 7215
A8: 6 | B8: 25 | D8: Kush Kiritkumar Jadia | E8: RITESH JAIN | F8: RITESH JAIN | G8: RELIANCE RETAIL LIMITED | H8: 40045 | I8: March | J8: 530868 | K8: 621560 | L8: 2420
A9: 7 | B9: 28 | D9: Vishal Arvindbhai Panchal | E9: Prashant Thakkar | F9: Prashant Thakkar | G9: J.K.& CO. | H9: 32209 | I9: March | J9: 253790 | K9: 178678 | L9: 7821
A10: 8 | B10: 38 | D10: Pankti Milap Patel | E10: Arpit Makhiyaviya | F10: Arpit Makhiyaviya | G10: PARTH ENTERPRISE | H10: 24133 | I10: March | J10: 253790 | K10: 178678 | L10: 7821
A11: 9 | B11: 42 | D11: Ashwin Narendrabhai Patel | E11: Vishal Prajapati | F11: Vishal Prajapati | G11: SAMIR TRADIND CO. | H11: 49800 | I11: April | J11: 740296 | K11: 228370 | L11: 7215
A12: 10 | B12: 43 | D12: Mudit Meghraj Parakh | E12: Arpit Makhiyaviya | F12: Arpit Makhiyaviya | G12: RAJBHARAT CASHEW COMPANY | H12: 40032 | I12: March | J12: 253790 | K12: 178678 | L12: 7821
A13: 11 | B13: 45 | D13: Nitin Tribhovan Makwana | E13: Vishal Prajapati | F13: Vishal Prajapati | G13: KIRTI TRADING COMPANY | H13: 58015 | I13: April | J13: 740296 | K13: 228370 | L13: 7215
A14: 12 | B14: 50 | D14: Kinjal Bipinbhai Hingu | E14: Nitin Tribhovan Makwana | F14: Vishal Prajapati | G14: RADHA DISTRIBUTORS | H14: 46200 | I14: April | J14: 740296 | K14: 228370 | L14: 7215
A15: 13 | B15: 51 | D15: Kalpesh NaginBhai Patel | E15: Vishal Prajapati | F15: Vishal Prajapati | G15: RADHA DISTRIBUTORS | H15: 42051 | I15: April | J15: 740296 | K15: 228370 | L15: 7215
A16: 14 | B16: 66 | D16: Avani Ashvinbhai Patel | E16: Arpit Makhiyaviya | F16: Arpit Makhiyaviya | G16: RADHA DISTRIBUTORS | H16: 11978 | I16: March | J16: 253790 | K16: 178678 | L16: 7821
A17: 15 | B17: 69 | D17: Samarth Rameshbhai Thesiya | E17: Vishal Arvindbhai Panchal | F17: Vishal Arvindbhai Panchal | G17: RADHA DISTRIBUTORS | H17: 49800 | I17: March | J17: 253790 | K17: 178678 | L17: 7821
A18: 16 | B18: 76 | D18: Jaldhi Mahendrabhai Darji | E18: MehulKumar JayeshKumar Patel | F18: Mayur Vinod kumar Jain | G18: MAHAVIR AGENCIES | H18: 49800 | I18: March | J18: 305532 | K18: 582610 | L18: 2895
A19: 17 | B19: 77 | D19: Kinjan Leela Jain | E19: Nilesh Dhirajlal Thakkar | F19: RITESH JAIN | G19: DEVHAR MARKETING PVT.LTD | H19: 39174 | I19: March | J19: 530868 | K19: 621560 | L19: 2420
A20: 18 | B20: 85 | D20: Mansi Shaileshbhai Kakkad | E20: Prashant Thakkar | F20: Prashant Thakkar | G20: DEVHAR MARKETING PVT.LTD | H20: 34103
A21: 19 | B21: 90 | D21: Darshan Rasikbhai Chudasama | E21: Pankti Milap Patel | F21: Arpit Makhiyaviya | G21: DEVHAR MARKETING PVT.LTD | H21: 32875 | I21: March | J21: 253790 | K21: 178678 | L21: 7821
A22: 20 | B22: 91 | D22: Ronak Prakashbhai Makhiyaviya | E22: Anil Babubhai Variya | F22: Vishal Prajapati | G22: RAHI ENTERPRISE | H22: 46200 | I22: April | J22: 740296 | K22: 228370 | L22: 7215
A23: 21 | B23: 95 | D23: Nishant Nitin Gajjar | E23: Arpit Makhiyaviya | F23: Arpit Makhiyaviya | G23: TIRUPATI AGENCIES | H23: 49800 | I23: March | J23: 253790 | K23: 178678 | L23: 7821
A24: 22 | B24: 100 | D24: Shital Ravi Gohil | E24: Mayur Vinod kumar Jain | F24: Mayur Vinod kumar Jain | G24: RAVI SALES | H24: 46200 | I24: March | J24: 305532 | K24: 582610 | L24: 2895
A25: 23 | B25: 101 | D25: Kaushal BharatBhai Jayswal | E25: MehulKumar JayeshKumar Patel | F25: Mayur Vinod kumar Jain | G25: RAVI SALES | H25: 54377 | I25: March | J25: 305532 | K25: 582610 | L25: 2895
A26: 24 | B26: 104 | D26: MehulKumar JayeshKumar Patel | E26: Mayur Vinod kumar Jain | F26: Mayur Vinod kumar Jain | G26: JALARAM SALES AGENCY | H26: 46226 | I26: March | J26: 305532 | K26: 582610 | L26: 2895
A27: 25 | B27: 112 | D27: Sahilkumar Amrutlal Bhuva | E27: Vishakha Bharatbhai Kathrecha | F27: RITESH JAIN | G27: KANERIYA OIL INDUSTRIES | H27: 49800 | I27: March | J27: 530868 | K27: 621560 | L27: 2420
A28: 26 | B28: 114 | D28: Paresh Rameshbhai Devatval | E28: Dhananjay Rajeshbhai Dhobi | F28: Dhananjay Rajeshbhai Dhobi | G28: NTC | H28: 33838 | I28: April | J28: 492328 | K28: 429516 | L28: 4762
A29: 27 | B29: 115 | D29: Pragneshkumar Lakhmanbhai Meniya | E29: Nilesh Dhirajlal Thakkar | F29: RITESH JAIN | G29: KQ BRO-SIS FOODS ENTERPRISE | H29: 49800 | I29: March | J29: 530868 | K29: 621560 | L29: 2420
A30: 28 | B30: 118 | D30: Mayur Vinod kumar Jain | E30: Prashant Thakkar | F30: Prashant Thakkar | G30: NTC | H30: 3590 | I30: March | J30: 305532 | K30: 582610 | L30: 2895
A31: 29 | B31: 121 | D31: Nensi Harsh Dhingani | E31: Vishal Arvindbhai Panchal | F31: Vishal Arvindbhai Panchal | G31: NTC | H31: -50503 | I31: March | J31: 253790 | K31: 178678 | L31: 7821
A32: 30 | B32: 128 | D32: Dhara Mansukhbhai Basida | E32: RITESH JAIN | F32: RITESH JAIN | G32: JAY AMBE TRADERS | H32: 5655 | I32: March | J32: 530868 | K32: 621560 | L32: 2420
... A35: 33 | B35: 131 | D35: Bikash Harenhandra Bhakat | E35: Dhananjay Rajeshbhai Dhobi | F35: Dhananjay Rajeshbhai Dhobi | G35: RADHA DISTRIBUTORS | H35: 44950 | I35: April | J35: 492328 | K35: 429516 | L35: 4762
A36: 34 | B36: 132 | D36: Dolly Dinesh Kumar Shah | E36: Chetana Ramasare Ravat | F36: Chetana Ramasare Ravat | G36: SHAURYA ENTERPRISE | H36: 49800
A37: 35 | B37: 133 | D37: Jigar Deepak Bhinde | E37: Ashwin Narendrabhai Patel | F37: Ashwin Narendrabhai Patel | G37: SHAURYA ENTERPRISE | H37: 40200
A38: 36 | B38: 137 | D38: Chetana Ramasare Ravat | E38: Prashant Thakkar | F38: Prashant Thakkar | G38: R C SALES | H38: 12867
A39: 37 | B39: 140 | D39: Arpita Harshadbhai Patel | E39: MehulKumar JayeshKumar Patel | F39: Mayur Vinod kumar Jain | G39: SAMIR TRADIND CO. | H39: 49800 | I39: March | J39: 305532 | K39: 582610 | L39: 2895
A40: 38 | B40: 141 | D40: Ashish Mansukhbhai Chaniyara | E40: Ashwin Narendrabhai Patel | F40: Vishal Prajapati | G40: RAJBHARAT CASHEW COMPANY | H40: 49800 | I40: April | J40: 740296 | K40: 228370 | L40: 7215
A41: 39 | B41: 146 | D41: Modi Vandana Hiteshbhai | E41: Kalpesh NaginBhai Patel | F41: Vishal Prajapati | G41: KIRTI TRADING COMPANY | H41: 46200 | I41: April | J41: 740296 | K41: 228370 | L41: 7215
A42: 40 | B42: 147 | D42: Manish Ambadas Patil | E42: Pankti Milap Patel | F42: Arpit Makhiyaviya | G42: SHAH TOKARSHI TRIBHOVANDAS | H42: 44190 | I42: March | J42: 253790 | K42: 178678 | L42: 7821
...

Sheet Sheet5
A1: Sr No | B1: Employee Code | C1: Column1 | D1: Employee name | E1: Manager Name RM1 | F1: Manager Name RM2
A2: 1 | B2: 4 | D2: Bansi Jayantibhai Sojitra | E2: MehulKumar JayeshKumar Patel | F2: Mayur Vinod kumar Jain
A3: 2 | B3: 9 | D3: Dhananjay Rajeshbhai Dhobi | E3: Prashant Thakkar | F3: Prashant Thakkar
A4: 3 | B4: 18 | D4: Priyank Mahendrabhai Patel | E4: Prashant Thakkar | F4: Prashant Thakkar
A5: 4 | B5: 13 | D5: Vivek Ashvinbhai Joshi | E5: Prashant Thakkar | F5: Prashant Thakkar
A6: 5 | B6: 22 | D6: Binal Rajeshbhai Kharecha | E6: Anil Babubhai Variya | F6: Vishal Prajapati
A7: 6 | B7: 25 | D7: Kush Kiritkumar Jadia | E7: RITESH JAIN | F7: RITESH JAIN
A8: 7 | B8: 28 | D8: Vishal Arvindbhai Panchal | E8: Prashant Thakkar | F8: Prashant Thakkar
A9: 8 | B9: 38 | D9: Pankti Milap Patel | E9: Arpit Makhiyaviya | F9: Arpit Makhiyaviya
A10: 9 | B10: 42 | D10: Ashwin Narendrabhai Patel | E10: Vishal Prajapati | F10: Vishal Prajapati
A11: 10 | B11: 43 | D11: Mudit Meghraj Parakh | E11: Arpit Makhiyaviya | F11: Arpit Makhiyaviya
A12: 11 | B12: 45 | D12: Nitin Tribhovan Makwana | E12: Vishal Prajapati | F12: Vishal Prajapati
A13: 12 | B13: 50 | D13: Kinjal Bipinbhai Hingu | E13: Nitin Tribhovan Makwana | F13: Vishal Prajapati
... A110: 109 | B110: 303 | D110: Zeelkumar Rabadiya | E110: Rahul Manojkumar Parikh | F110: Rahul Manojkumar Parikh

Sheet Sheet6
A1: Sr No | B1: Code | C1: Employee Name | D1: Project
A2: 1 | B2: 3 | C2: Hetal Arunbhai Agravat | D2: VSI-Nationwide
A3: 2 | B3: 4 | C3: Bansi Jayantibhai Sojitra | D3: VSI-Nationwide
A4: 3 | B4: 9 | C4: Dhananjay Rajeshbhai Dhobi | D4: IFM
A5: 4 | B5: 13 | C5: Vivek Ashvinbhai Joshi | D5: Risk AI/Genome
A6: 5 | B6: 18 | C6: Priyank Mahendrabhai Patel | D6: Blitzz
A7: 6 | B7: 22 | C7: Binal Rajeshbhai Kharecha | D7: Blitzz
A8: 7 | B8: 25 | C8: Kush Kiritkumar Jadia | D8: Vsite-RemoteVal
A9: 8 | B9: 28 | C9: Vishal Arvindbhai Panchal | D9: Genome
A10: 9 | B10: 38 | C10: Pankti Milap Patel | D10: Genome
A11: 10 | B11: 42 | C11: Ashwin Narendrabhai Patel | D11: Blitzz
A12: 11 | B12: 43 | C12: Mudit Meghraj Parakh | D12: Genome
A13: 12 | B13: 45 | C13: Nitin Tribhovan Makwana | D13: Blitzz
... A110: 109 | B110: 116 | C110: Arjun Lal Rabari | D110: Admin

Sheet Project_income
A1: Sr. No. | B1: Buyer | C1: Invoice Date | D1: Invoice Month | E1: Column2 | F1: Invoice# | G1: Due Date | H1: Invoice Amount | I1: Received Amount in INR | J1: Received Amount | K1: Received Date | L1: Pending Amount | M1: Column1 | O1: Buyer | P1: Month | Q1: Amount Raised | R1: Amount Raised in INR | S1: Received Amount | T1: Amount Received in INR | U1: Pending Amount | V1: Table28.Project
A2: 1 | B2: RADHA DISTRIBUTORS | C2: 44652 | D2: 44986 | E2: =TEXT(Project_Payments1617[[#This Row],[Invoice Month]],"mmmm") -> March | F2: 1 | G2: 45023 | H2: 10000 | I2: =J2*82 -> 621560 | J2: 7580 | K2: 44657 | L2: =H2-J2 -> 2420 | M2: =3516668.21/47096 -> 74.67021 | O2: RADHA DISTRIBUTORS | P2: March | Q2: 6474 | R2: =Table35[[#This Row],[Amount Raised]]*82 -> 530868 | S2: 7580 | T2: =Table35[[#This Row],[Received Amount]]*82 -> 621560 | U2: 2420 | V2: RADHA DISTRIBUTORS
A3: 2 | B3: RADHA DISTRIBUTORS | C3: 44654 | D3: 44621 | E3: =TEXT(Project_Payments1617[[#This Row],[Invoice Month]],"mmmm") -> March | F3: 2 | G3: 44668 | H3: 10000 | I3: =J3*82 -> 178678 | J3: 2179 | K3: 44670 | L3: =H3-J3 -> 7821 | O3: RADHA DISTRIBUTORS | P3: March | Q3: 3095 | R3: =Table35[[#This Row],[Amount Raised]]*82 -> 253790 | S3: 2179 | T3: =Table35[[#This Row],[Received Amount]]*82 -> 178678 | U3: 7821 | V3: RADHA DISTRIBUTORS
A4: 3 | B4: RADHA DISTRIBUTORS | C4: 44655 | D4: 44621 | E4: =TEXT(Project_Payments1617[[#This Row],[Invoice Month]],"mmmm") -> March | F4: 3 | G4: 44664 | H4: 10000 | I4: =J4*82 -> 154816 | J4: 1888 | K4: 44669 | L4: =H4-J4 -> 8112 | O4: RADHA DISTRIBUTORS | P4: March | Q4: 5716 | R4: =Table35[[#This Row],[Amount Raised]]*82 -> 468712 | S4: 1888 | T4: =Table35[[#This Row],[Received Amount]]*82 -> 154816 | U4: 8112 | V4: RADHA DISTRIBUTORS
A5: 4 | B5: RADHA DISTRIBUTORS | C5: 44656 | D5: 44621 | E5: =TEXT(Project_Payments1617[[#This Row],[Invoice Month]],"mmmm") -> March | F5: 4 | G5: 44662 | H5: 10000 | I5: =J5*82 -> 582610 | J5: 7105 | K5: 44669 | L5: =H5-J5 -> 2895 | O5: RADHA DISTRIBUTORS | P5: March | Q5: 3726 | R5: =Table35[[#This Row],[Amount Raised]]*82 -> 305532 | S5: 7105 | T5: =Table35[[#This Row],[Received Amount]]*82 -> 582610 | U5: 2895 | V5: RADHA DISTRIBUTORS
A6: 5 | B6: MAHAVIR AGENCIES | C6: 44665 | D6: Feb-Mar | E6: =TEXT(Project_Payments1617[[#This Row],[Invoice Month]],"mmmm") -> Feb-Mar | F6: 5 | G6: 44674 | H6: 10000 | I6: =J6*82 -> 180072 | J6: 2196 | K6: 44680 | L6: =H6-J6 -> 7804 | O6: RADHA DISTRIBUTORS | P6: Feb-Mar | Q6: 6293 | R6: =Table35[[#This Row],[Amount Raised]]*82 -> 516026 | S6: 2196 | T6: =Table35[[#This Row],[Received Amount]]*82 -> 180072 | U6: 7804 | V6: MAHAVIR AGENCIES
A7: 6 | B7: DEVHAR MARKETING PVT.LTD | C7: 44672 | D7: 44652 | E7: =TEXT(Project_Payments1617[[#This Row],[Invoice Month]],"mmmm") -> April | F7: 6 | G7: 44686 | H7: 10000 | I7: =J7*82 -> 429516 | J7: 5238 | K7: 44701 | L7: =H7-J7 -> 4762 | M7: TDS | O7: RADHA DISTRIBUTORS | P7: April | Q7: 6004 | R7: =Table35[[#This Row],[Amount Raised]]*82 -> 492328 | S7: 5238 | T7: =Table35[[#This Row],[Received Amount]]*82 -> 429516 | U7: 4762 | V7: DEVHAR MARKETING PVT.LTD
A8: 7 | B8: DEVHAR MARKETING PVT.LTD | C8: 44676 | D8: 44652 | E8: =TEXT(Project_Payments1617[[#This Row],[Invoice Month]],"mmmm") -> April | F8: 7 | G8: 44690 | H8: 10000 | I8: =J8*82 -> 480848 | J8: 5864 | K8: 44701 | L8: =H8-J8 -> 4136 | M8: TDS | O8: MAHAVIR AGENCIES | P8: April | Q8: 7906 | R8: =Table35[[#This Row],[Amount Raised]]*82 -> 648292 | S8: 5864 | T8: =Table35[[#This Row],[Received Amount]]*82 -> 480848 | U8: 4136 | V8: DEVHAR MARKETING PVT.LTD
A9: 8 | B9: DEVHAR MARKETING PVT.LTD | C9: 44679 | E9: =TEXT(Project_Payments1617[[#This Row],[Invoice Month]],"mmmm") -> January | F9: 8 | G9: 44688 | H9: 10000 | I9: =J9*82 -> 308484 | J9: 3762 | K9: 44743 | L9: =H9-J9 -> 6238 | O9: DEVHAR MARKETING PVT.LTD | P9: January | Q9: 6640 | R9: =Table35[[#This Row],[Amount Raised]]*82 -> 544480 | S9: 3762 | T9: =Table35[[#This Row],[Received Amount]]*82 -> 308484 | U9: 6238 | V9: DEVHAR MARKETING PVT.LTD
A10: 9 | B10: RAHI ENTERPRISE | C10: 44682 | D10: 44652 | E10: =TEXT(Project_Payments1617[[#This Row],[Invoice Month]],"mmmm") -> April | F10: 9 | G10: 44688 | H10: 10000 | I10: =J10*82 -> 531934 | J10: 6487 | K10: 44686 | L10: =H10-J10 -> 3513 | O10: DEVHAR MARKETING PVT.LTD | P10: April | Q10: 7456 | R10: =Table35[[#This Row],[Amount Raised]]*82 -> 611392 | S10: 6487 | T10: =Table35[[#This Row],[Received Amount]]*82 -> 531934 | U10: 3513 | V10: RAHI ENTERPRISE
A11: 10 | B11: TIRUPATI AGENCIES | C11: 44683 | D11: 44652 | E11: =TEXT(Project_Payments1617[[#This Row],[Invoice Month]],"mmmm") -> April | F11: 10 | G11: 44697 | H11: 10000 | I11: =J11*82 -> 228370 | J11: 2785 | K11: 44691 | L11: =H11-J11 -> 7215 | M11: =1798358.9/23474 -> 76.610671 | O11: DEVHAR MARKETING PVT.LTD | P11: April | Q11: 9028 | R11: =Table35[[#This Row],[Amount Raised]]*82 -> 740296 | S11: 2785 | T11: =Table35[[#This Row],[Received Amount]]*82 -> 228370 | U11: 7215 | V11: TIRUPATI AGENCIES
A12: 11 | B12: RAVI SALES | C12: 44683 | D12: 44652 | E12: =TEXT(Project_Payments1617[[#This Row],[Invoice Month]],"mmmm") -> April | F12: 11 | G12: 44692 | H12: 10000 | I12: =J12*82 -> 341776 | J12: 4168 | K12: 44698 | L12: =H12-J12 -> 5832 | O12: DEVHAR MARKETING PVT.LTD | P12: April | Q12: 4587 | R12: =Table35[[#This Row],[Amount Raised]]*82 -> 376134 | S12: 4168 | T12: =Table35[[#This Row],[Received Amount]]*82 -> 341776 | U12: 5832 | V12: RAVI SALES
A13: 12 | B13: RAVI SALES | C13: 44685 | D13: 44652 | E13: =TEXT(Project_Payments1617[[#This Row],[Invoice Month]],"mmmm") -> April | F13: 12 | G13: 44699 | H13: 10000 | I13: =J13*82 -> 326114 | J13: 3977 | K13: 44699 | L13: =H13-J13 -> 6023 | O13: RAHI ENTERPRISE | P13: April | Q13: 2181 | R13: =Table35[[#This Row],[Amount Raised]]*82 -> 178842 | S13: 3977 | T13: =Table35[[#This Row],[Received Amount]]*82 -> 326114 | U13: 6023 | V13: RAVI SALES
A14: 13 | B14: JALARAM SALES AGENCY | C14: Invoice# 13 Skipping for any adjustment | O14: Invoice# 13 Skipping for any adjustment | Q14: 4363 | R14: =Table35[[#This Row],[Amount Raised]]*82 -> 357766 | T14: =Table35[[#This Row],[Received Amount]]*82 -> 0 | V14: JALARAM SALES AGENCY
A15: 14 | B15: KANERIYA OIL INDUSTRIES | C15: 44685 | D15: 44652 | E15: =TEXT(Project_Payments1617[[#This Row],[Invoice Month]],"mmmm") -> April | F15: 14 | G15: 44691 | H15: 10000 | I15: =J15*82 -> 211396 | J15: 2578 | K15: 44692 | L15: =H15-J15 -> 7422 | O15: TIRUPATI AGENCIES | P15: April | Q15: 6029 | R15: =Table35[[#This Row],[Amount Raised]]*82 -> 494378 | S15: 2578 | T15: =Table35[[#This Row],[Received Amount]]*82 -> 211396 | U15: 7422 | V15: KANERIYA OIL INDUSTRIES
A16: 15 | B16: NTC | C16: 44701 | D16: 44682 | E16: =TEXT(Project_Payments1617[[#This Row],[Invoice Month]],"mmmm") -> May | F16: 15 | G16: 44715 | H16: 10000 | I16: =J16*82 -> 205738 | J16: 2509 | K16: 44732 | L16: =H16-J16 -> 7491 | M16: TDS | O16: RAVI SALES | P16: May | Q16: 9086 | R16: =Table35[[#This Row],[Amount Raised]]*82 -> 745052 | S16: 2509 | T16: =Table35[[#This Row],[Received Amount]]*82 -> 205738 | U16: 7491 | V16: NTC
A17: 16 | B17: KQ BRO-SIS FOODS ENTERPRISE | C17: 44707 | D17: 44682 | E17: =TEXT(Project_Payments1617[[#This Row],[Invoice Month]],"mmmm") -> May | F17: 16 | G17: 44721 | H17: 10000 | I17: =J17*82 -> 621560 | J17: 7580 | K17: 44732 | L17: =H17-J17 -> 2420 | M17: TDS | O17: RAVI SALES | P17: May | Q17: 8722 | R17: =Table35[[#This Row],[Amount Raised]]*82 -> 715204 | S17: 7580 | T17: =Table35[[#This Row],[Received Amount]]*82 -> 621560 | U17: 2420 | V17: KQ BRO-SIS FOODS ENTERPRISE
A18: 17 | B18: NTC | C18: 44711 | D18: 44682 | E18: =TEXT(Project_Payments1617[[#This Row],[Invoice Month]],"mmmm") -> May | F18: 17 | G18: 44717 | H18: 10000 | I18: =J18*82 -> 425990 | J18: 5195 | K18: 44741 | L18: =H18-J18 -> 4805 | O18: JALARAM SALES AGENCY | P18: May | Q18: 5688 | R18: =Table35[[#This Row],[Amount Raised]]*82 -> 466416 | S18: 5195 | T18: =Table35[[#This Row],[Received Amount]]*82 -> 425990 | U18: 4805 | V18: NTC
A19: 18 | B19: NTC | C19: 44713 | D19: 44682 | E19: =TEXT(Project_Payments1617[[#This Row],[Invoice Month]],"mmmm") -> May | F19: 18 | G19: 44719 | H19: 10000 | I19: =J19*82 -> 632056 | J19: 7708 | K19: 44720 | L19: =H19-J19 -> 2292 | O19: KANERIYA OIL INDUSTRIES | P19: May | Q19: 6637 | R19: =Table35[[#This Row],[Amount Raised]]*82 -> 544234 | S19: 7708 | T19: =Table35[[#This Row],[Received Amount]]*82 -> 632056 | U19: 2292 | V19: NTC
A20: 19 | B20: JAY AMBE TRADERS | C20: 44714 | D20: 44682 | E20: =TEXT(Project_Payments1617[[#This Row],[Invoice Month]],"mmmm") -> May | F20: 19 | G20: 44728 | H20: 10000 | I20: =J20*82 -> 342678 | J20: 4179 | K20: 44715 | L20: =H20-J20 -> 5821 | M20: =2037026.96/26520 -> 76.810971 | O20: NTC | P20: May | Q20: 7562 | R20: =Table35[[#This Row],[Amount Raised]]*82 -> 620084 | S20: 4179 | T20: =Table35[[#This Row],[Received Amount]]*82 -> 342678 | U20: 5821 | V20: JAY AMBE TRADERS
A21: 20 | B21: RADHA DISTRIBUTORS | C21: 44715 | D21: 44682 | E21: =TEXT(Project_Payments1617[[#This Row],[Invoice Month]],"mmmm") -> May | F21: 20 | G21: 44729 | H21: 10000 | I21: =J21*82 -> 143500 | J21: 1750 | K21: 44726 | L21: =H21-J21 -> 8250 | O21: KQ BRO-SIS FOODS ENTERPRISE | P21: May | Q21: 4047 | R21: =Table35[[#This Row],[Amount Raised]]*82 -> 331854 | S21: 1750 | T21: =Table35[[#This Row],[Received Amount]]*82 -> 143500 | U21: 8250 | V21: RADHA DISTRIBUTORS
A22: 21 | B22: RADHA DISTRIBUTORS | C22: 44716 | D22: 44682 | E22: =TEXT(Project_Payments1617[[#This Row],[Invoice Month]],"mmmm") -> May | F22: 21 | G22: 44722 | H22: 10000 | I22: =J22*82 -> 408688 | J22: 4984 | K22: 44728 | L22: =H22-J22 -> 5016 | O22: NTC | P22: May | Q22: 4928 | R22: =Table35[[#This Row],[Amount Raised]]*82 -> 404096 | S22: 4984 | T22: =Table35[[#This Row],[Received Amount]]*82 -> 408688 | U22: 5016 | V22: RADHA DISTRIBUTORS
A23: 22 | B23: RADHA DISTRIBUTORS | C23: 44718 | D23: 44682 | E23: =TEXT(Project_Payments1617[[#This Row],[Invoice Month]],"mmmm") -> May | F23: 22 | G23: 44727 | H23: 10000 | I23: =J23*82 -> 244114 | J23: 2977 | K23: 44725 | L23: =H23-J23 -> 7023 | O23: JAY AMBE TRADERS | P23: May | Q23: 8723 | R23: =Table35[[#This Row],[Amount Raised]]*82 -> 715286 | S23: 2977 | T23: =Table35[[#This Row],[Received Amount]]*82 -> 244114 | U23: 7023 | V23: RADHA DISTRIBUTORS
A24: 23 | B24: SHAURYA ENTERPRISE | C24: 44734 | D24: 44713 | E24: =TEXT(Project_Payments1617[[#This Row],[Invoice Month]],"mmmm") -> June | F24: 23 | G24: 44748 | H24: 10000 | I24: =J24*82 -> 266254 | J24: 3247 | K24: 44762 | L24: =H24-J24 -> 6753 | M24: TDS | O24: NTC | P24: June | Q24: 1769 | R24: =Table35[[#This Row],[Amount Raised]]*82 -> 145058 | S24: 3247 | T24: =Table35[[#This Row],[Received Amount]]*82 -> 266254 | U24: 6753 | V24: SHAURYA ENTERPRISE
A25: 24 | B25: SHAURYA ENTERPRISE | C25: 44734 | D25: 44713 | E25: =TEXT(Project_Payments1617[[#This Row],[Invoice Month]],"mmmm") -> June | F25: 24 | G25: 44748 | H25: 10000 | I25: =J25*82 -> 458626 | J25: 5593 | K25: 44762 | L25: =H25-J25 -> 4407 | M25: TDS | O25: JAY AMBE TRADERS | P25: June | Q25: 6866 | R25: =Table35[[#This Row],[Amount Raised]]*82 -> 563012 | S25: 5593 | T25: =Table35[[#This Row],[Received Amount]]*82 -> 458626 | U25: 4407 | V25: SHAURYA ENTERPRISE
A26: 25 | B26: R C SALES | C26: 44736 | D26: May-June-2022 | E26: =TEXT(Project_Payments1617[[#This Row],[Invoice Month]],"mmmm") -> May-June-2022 | F26: 25 | G26: 44750 | H26: 10000 | I26: =J26*82 -> 492820 | J26: 6010 | K26: 44753 | L26: =H26-J26 -> 3990 | M26: =213322.58/2775 -> 76.873002 | O26: RADHA DISTRIBUTORS | P26: May-June-2022 | Q26: 2006 | R26: =Table35[[#This Row],[Amount Raised]]*82 -> 164492 | S26: 6010 | T26: =Table35[[#This Row],[Received Amount]]*82 -> 492820 | U26: 3990 | V26: R C SALES
A27: 26 | B27: SAMIR TRADIND CO. | C27: 44742 | D27: 44713 | E27: =TEXT(Project_Payments1617[[#This Row],[Invoice Month]],"mmmm") -> June | F27: 26 | G27: 44748 | H27: 10000 | I27: =J27*82 -> 412460 | J27: 5030 | K27: 44748 | L27: =H27-J27 -> 4970 | O27: RADHA DISTRIBUTORS | P27: June | Q27: 4543 | R27: =Table35[[#This Row],[Amount Raised]]*82 -> 372526 | S27: 5030 | T27: =Table35[[#This Row],[Received Amount]]*82 -> 412460 | U27: 4970 | V27: SAMIR TRADIND CO.
A28: 27 | B28: RAJBHARAT CASHEW COMPANY | C28: 44745 | D28: 44713 | E28: =TEXT(Project_Payments1617[[#This Row],[Invoice Month]],"mmmm") -> June | F28: 27 | G28: 44759 | H28: 10000 | I28: =J28*82 -> 317586 | J28: 3873 | K28: 44757 | L28: =H28-J28 -> 6127 | O28: RADHA DISTRIBUTORS | P28: June | Q28: 2434 | R28: =Table35[[#This Row],[Amount Raised]]*82 -> 199588 | S28: 3873 | T28: =Table35[[#This Row],[Received Amount]]*82 -> 317586 | U28: 6127 | V28: RAJBHARAT CASHEW COMPANY
A29: 28 | B29: KIRTI TRADING COMPANY | C29: 44746 | D29: 44713 | E29: =TEXT(Project_Payments1617[[#This Row],[Invoice Month]],"mmmm") -> June | F29: 28 | G29: 44752 | H29: 10000 | I29: =J29*82 -> 560552 | J29: 6836 | K29: 44762 | L29: =H29-J29 -> 3164 | O29: SHAURYA ENTERPRISE | P29: June | Q29: 8994 | R29: =Table35[[#This Row],[Amount Raised]]*82 -> 737508 | S29: 6836 | T29: =Table35[[#This Row],[Received Amount]]*82 -> 560552 | U29: 3164 | V29: KIRTI TRADING COMPANY
A30: 29 | B30: SHAH TOKARSHI TRIBHOVANDAS | C30: 44746 | D30: 44713 | E30: =TEXT(Project_Payments1617[[#This Row],[Invoice Month]],"mmmm") -> June | F30: 29 | G30: 44752 | H30: 10000 | I30: =J30*82 -> 653130 | J30: 7965 | K30: 44760 | L30: =H30-J30 -> 2035 | O30: R C SALES | P30: June | Q30: 2142 | R30: =Table35[[#This Row],[Amount Raised]]*82 -> 175644 | S30: 7965 | T30: =Table35[[#This Row],[Received Amount]]*82 -> 653130 | U30: 2035 | V30: SHAH TOKARSHI TRIBHOVANDAS
A31: 30 | B31: SAGAR SALES | C31: 44746 | D31: 44713 | E31: =TEXT(Project_Payments1617[[#This Row],[Invoice Month]],"mmmm") -> June | F31: 30 | G31: 44760 | H31: 10000 | I31: =J31*82 -> 293068 | J31: 3574 | K31: 44754 | L31: =H31-J31 -> 6426 | M31: =1996558.78/25300 -> 78.915367 | O31: SHAURYA ENTERPRISE | P31: June | Q31: 1408 | R31: =Table35[[#This Row],[Amount Raised]]*82 -> 115456 | S31: 3574 | T31: =Table35[[#This Row],[Received Amount]]*82 -> 293068 | U31: 6426 | V31: SAGAR SALES
